Traceback (most recent call last):
  File "/Users/stephenjerome/Desktop/SteveHorsesPro/steve_horses_pro.py", line 259, in <module>
    main()
  File "/Users/stephenjerome/Desktop/SteveHorsesPro/steve_horses_pro.py", line 252, in main
    cards, chosen, meets_count = fetch_cards_for_today()
  File "/Users/stephenjerome/Desktop/SteveHorsesPro/steve_horses_pro.py", line 138, in fetch_cards_for_today
    meets = _get_json("/v1/north-america/meets", {"start_date":today,"end_date":today}) if USE_API else {"meets":[]}
  File "/Users/stephenjerome/Desktop/SteveHorsesPro/steve_horses_pro.py", line 32, in _get_json
    with urlopen(req, timeout=30, context=CTX) as r:
  File "/Library/Developer/CommandLineTools/Library/Frameworks/Python3.framework/Versions/3.9/lib/python3.9/urllib/request.py", line 214, in urlopen
    return opener.open(url, data, timeout)
  File "/Library/Developer/CommandLineTools/Library/Frameworks/Python3.framework/Versions/3.9/lib/python3.9/urllib/request.py", line 523, in open
    response = meth(req, response)
  File "/Library/Developer/CommandLineTools/Library/Frameworks/Python3.framework/Versions/3.9/lib/python3.9/urllib/request.py", line 632, in http_response
    response = self.parent.error(
  File "/Library/Developer/CommandLineTools/Library/Frameworks/Python3.framework/Versions/3.9/lib/python3.9/urllib/request.py", line 561, in error
    return self._call_chain(*args)
  File "/Library/Developer/CommandLineTools/Library/Frameworks/Python3.framework/Versions/3.9/lib/python3.9/urllib/request.py", line 494, in _call_chain
    result = func(*args)
  File "/Library/Developer/CommandLineTools/Library/Frameworks/Python3.framework/Versions/3.9/lib/python3.9/urllib/request.py", line 641, in http_error_default
    raise HTTPError(req.full_url, code, msg, hdrs, fp)
urllib.error.HTTPError: HTTP Error 401: Unauthorized
